---
date: 2024-01-26 00:51:39.450052-07:00
description: "\uC5B4\uB5BB\uAC8C: Elixir\uC5D0\uC11C\uB294 \uC8FC\uB85C \uD328\uD134\
  \ \uB9E4\uCE6D\uACFC `case` \uBB38\uC744 \uC0AC\uC6A9\uD558\uC5EC \uB2E4\uB978 \uACB0\
  \uACFC\uB4E4, \uC5D0\uB7EC\uB97C \uD3EC\uD568\uD558\uC5EC \uCC98\uB9AC\uD569\uB2C8\
  \uB2E4."
lastmod: '2024-03-13T22:44:54.732536-06:00'
model: gpt-4-1106-preview
summary: "Elixir\uC5D0\uC11C\uB294 \uC8FC\uB85C \uD328\uD134 \uB9E4\uCE6D\uACFC `case`\
  \ \uBB38\uC744 \uC0AC\uC6A9\uD558\uC5EC \uB2E4\uB978 \uACB0\uACFC\uB4E4, \uC5D0\uB7EC\
  \uB97C \uD3EC\uD568\uD558\uC5EC \uCC98\uB9AC\uD569\uB2C8\uB2E4."
title: "\uC5D0\uB7EC \uCC98\uB9AC\uD558\uAE30"
weight: 16
---

## 어떻게:
Elixir에서는 주로 패턴 매칭과 `case` 문을 사용하여 다른 결과들, 에러를 포함하여 처리합니다.

```elixir
defmodule Example do
  def divide(a, b) do
    case b do
      0 -> {:error, "0으로 나눌 수 없습니다."}
      _ -> {:ok, a / b}
    end
  end
end

# 성공적인 나눗셈
{:ok, result} = Example.divide(10, 2)
IO.puts("10 / 2는 #{result}입니다")

# 0으로 나누려는 시도
{:error, reason} = Example.divide(10, 0)
IO.puts("에러: #{reason}")
```

샘플 출력:
```
10 / 2는 5.0입니다
에러: 0으로 나눌 수 없습니다.
```

이 Elixir 코드를 실행하면, 입력에 따라 성공적인 나눗셈 결과나 에러 메시지를 얻을 수 있습니다. 여기서는 충돌이 없습니다!

## 자세히 알아보기
오래전에는 에러 처리가 주로 반환 값들을 확인하는 것으로 이루어졌습니다. 하지만 Elixir의 함수형 뿌리를 감안할 때, 우리는 `{:ok, value}` 또는 `{:error, reason}`과 같은 태그가 붙은 튜플과 패턴 매칭을 사용하는데, 이는 더 우아합니다.

Elixir에서는 에러처리를 위한 다른 방법들도 있습니다:

- **Elixir의 `try`와 `rescue`**는 명령형 언어에서의 전통적인 `try-catch`와 비슷하지만, Elixir에서는 명시성을 선호하기 때문에 덜 자주 사용됩니다.
- **Supervisors와 GenServers**, Elixir OTP 프레임워크의 일부로, 장애 내성에 관한 것입니다. 이들은 코드 프로세스를 감시하여 무언가 잘못되면 재시작할 준비가 되어 있습니다.

구현 측면에서, Elixir는 Erlang의 견고함을 이어받습니다. 에러를 패턴 매칭과 함수형의 장점을 사용하여 처리되어야 하는 메시지 타입 중 하나로 취급합니다.

## 또한 보기
Elixir에서의 에러 처리에 대해 더 알아보려면 아래 참조하세요:

- Elixir의 공식 가이드, [에러 처리](https://elixir-lang.org/getting-started/try-catch-and-rescue.html).
- [프로세스와 OTP에 대해](https://elixir-lang.org/getting-started/mix-otp/introduction-to-mix.html) 더 알아보세요.
- Elixir 포럼에서는 질문을 할 수 있는 좋은 장소입니다: [https://elixirforum.com](https://elixirforum.com).
